Workbook
Name Slicer_Class: #N/A
Name Slicer_Section: #N/A
Name Slicer_Gender: #N/A
Name Slicer_Fee_Status: #N/A

Sheet Dashboard
B1: STUDENT MANAGEMENT SYSTEM DASHBOARD
B3: TOTAL STUDENTS | D3: PASS / FAIL | F3: CLASS AVERAGE % | H3: TOP SCORER
B4: =Summary!B4 -> 60 | D4: =CONCATENATE(Summary!B5," / ",Summary!B6) -> 47 / 13 | F4: =Summary!B7 -> 67.166667 | H4: =Summary!B11 -> Tanvi Verma
B6: PENDING FEES
B7: =Summary!B8 -> 33
B9: Grade Distribution | H9: Class-wise Pass Count
B25: Class-wise Average Percentage

Sheet Grade_Scale
A1: GRADE SCALE (Lookup Table for VLOOKUP)
A2: Min Marks (%) | B2: Max Marks (%) | C2: Grade | E2: NOTE: VLOOKUP with the 4th argument TRUE (approximate match) requires the lookup column ('Min Marks %') to be sorted ascending - it is, by design, for this table.
A3: 0 | B3: 39 | C3: F
A4: 40 | B4: 49 | C4: D
A5: 50 | B5: 59 | C5: C
A6: 60 | B6: 74 | C6: B
A7: 75 | B7: 89 | C7: A
A8: 90 | B8: 100 | C8: A+

Sheet pivot table
A3: Section | B3: Gender | C3: Class | D3: Count of Result | E3: Average of Percentage (%)
A4: A | D4: 19 | E4: 67.252632
B5: Female | D5: 9 | E5: 66.044444
C6: 10 | D6: 2 | E6: 65
C7: 6 | D7: 1 | E7: 61.6
C8: 7 | D8: 2 | E8: 68.9
C9: 8 | D9: 2 | E9: 68.9
C10: 9 | D10: 2 | E10: 63.6
B11: Male | D11: 10 | E11: 68.34
C12: 10 | D12: 4 | E12: 67.15
C13: 6 | D13: 3 | E13: 61.6
C14: 7 | D14: 1 | E14: 82.4
C15: 8 | D15: 1 | E15: 69.4
C16: 9 | D16: 1 | E16: 78.2
A17: B | D17: 21 | E17: 66.761905
B18: Female | D18: 11 | E18: 67.618182
C19: 10 | D19: 1 | E19: 53
C20: 6 | D20: 2 | E20: 66.1
C21: 7 | D21: 3 | E21: 69
C22: 8 | D22: 2 | E22: 69.3
C23: 9 | D23: 3 | E23: 71
B24: Male | D24: 10 | E24: 65.82
C25: 10 | D25: 2 | E25: 69.2
C26: 6 | D26: 2 | E26: 57.2
C27: 7 | D27: 2 | E27: 66.3
C28: 8 | D28: 2 | E28: 63.9
C29: 9 | D29: 2 | E29: 72.5
A30: C | D30: 20 | E30: 67.51
B31: Female | D31: 9 | E31: 67.022222
C32: 10 | D32: 1 | E32: 85
C33: 6 | D33: 3 | E33: 67.733333
C34: 7 | D34: 3 | E34: 63
C35: 8 | D35: 1 | E35: 54.8
C36: 9 | D36: 1 | E36: 71.2
B37: Male | D37: 11 | E37: 67.909091
C38: 10 | D38: 2 | E38: 71.6
C39: 6 | D39: 2 | E39: 71.4
C40: 7 | D40: 2 | E40: 68.1
C41: 8 | D41: 2 | E41: 67.4
C42: 9 | D42: 3 | E42: 63.333333
...

Sheet Students_Data
A1: Student ID | B1: Student Name | C1: Class | D1: Section | E1: Gender | F1: Subject | G1: Maths | H1: Science | I1: English | J1: Computer | K1: Social Studies | L1: Total Marks | M1: Percentage (%) | N1: Grade | O1: Result | P1: Attendance (%) | Q1: Fee Status | R1: Remarks
A2: STU2025001 | B2: Ananya Patel | C2: 9 | D2: C | E2: Male | F2: Science Stream | G2: 47 | H2: 81 | I2: 42 | J2: 99 | K2: 62 | L2: =SUM(G2:K2) -> 331 | M2: =L2/500*100 -> 66.2 | N2: =VLOOKUP(M2,Grade_Scale!$A$3:$C$8,3,TRUE()) -> B | O2: =IF(AND(G2>=40,H2>=40,I2>=40,J2>=40,K2>=40),"Pass","Fail") -> Pass | P2: 62 | Q2: Paid | R2: =IF(O2="Fail","Needs Improvement",IF(M2>=90,"Excellent",IF(M2>=75,"Very Good",IF(M2>=60,"Good","Average")))) -> Good
A3: STU2025002 | B3: Sneha Singh | C3: 6 | D3: A | E3: Male | F3: Arts Stream | G3: 89 | H3: 42 | I3: 50 | J3: 63 | K3: 42 | L3: =SUM(G3:K3) -> 286 | M3: =L3/500*100 -> 57.2 | N3: =VLOOKUP(M3,Grade_Scale!$A$3:$C$8,3,TRUE()) -> C | O3: =IF(AND(G3>=40,H3>=40,I3>=40,J3>=40,K3>=40),"Pass","Fail") -> Pass | P3: 96 | Q3: Pending | R3: =IF(O3="Fail","Needs Improvement",IF(M3>=90,"Excellent",IF(M3>=75,"Very Good",IF(M3>=60,"Good","Average")))) -> Average
A4: STU2025003 | B4: Vivaan Reddy | C4: 6 | D4: C | E4: Male | F4: Commerce Stream | G4: 88 | H4: 53 | I4: 50 | J4: 74 | K4: 58 | L4: =SUM(G4:K4) -> 323 | M4: =L4/500*100 -> 64.6 | N4: =VLOOKUP(M4,Grade_Scale!$A$3:$C$8,3,TRUE()) -> B | O4: =IF(AND(G4>=40,H4>=40,I4>=40,J4>=40,K4>=40),"Pass","Fail") -> Pass | P4: 66 | Q4: Paid | R4: =IF(O4="Fail","Needs Improvement",IF(M4>=90,"Excellent",IF(M4>=75,"Very Good",IF(M4>=60,"Good","Average")))) -> Good
A5: STU2025004 | B5: Diya Verma | C5: 10 | D5: C | E5: Male | F5: Arts Stream | G5: 42 | H5: 61 | I5: 98 | J5: 89 | K5: 75 | L5: =SUM(G5:K5) -> 365 | M5: =L5/500*100 -> 73 | N5: =VLOOKUP(M5,Grade_Scale!$A$3:$C$8,3,TRUE()) -> B | O5: =IF(AND(G5>=40,H5>=40,I5>=40,J5>=40,K5>=40),"Pass","Fail") -> Pass | P5: 89 | Q5: Pending | R5: =IF(O5="Fail","Needs Improvement",IF(M5>=90,"Excellent",IF(M5>=75,"Very Good",IF(M5>=60,"Good","Average")))) -> Good
A6: STU2025005 | B6: Diya Iyer | C6: 7 | D6: A | E6: Male | F6: Science Stream | G6: 73 | H6: 98 | I6: 78 | J6: 92 | K6: 71 | L6: =SUM(G6:K6) -> 412 | M6: =L6/500*100 -> 82.4 | N6: =VLOOKUP(M6,Grade_Scale!$A$3:$C$8,3,TRUE()) -> A | O6: =IF(AND(G6>=40,H6>=40,I6>=40,J6>=40,K6>=40),"Pass","Fail") -> Pass | P6: 98 | Q6: Paid | R6: =IF(O6="Fail","Needs Improvement",IF(M6>=90,"Excellent",IF(M6>=75,"Very Good",IF(M6>=60,"Good","Average")))) -> Very Good
A7: STU2025006 | B7: Vihaan Nair | C7: 9 | D7: A | E7: Female | F7: Science Stream | G7: 97 | H7: 88 | I7: 40 | J7: 44 | K7: 75 | L7: =SUM(G7:K7) -> 344 | M7: =L7/500*100 -> 68.8 | N7: =VLOOKUP(M7,Grade_Scale!$A$3:$C$8,3,TRUE()) -> B | O7: =IF(AND(G7>=40,H7>=40,I7>=40,J7>=40,K7>=40),"Pass","Fail") -> Pass | P7: 81 | Q7: Pending | R7: =IF(O7="Fail","Needs Improvement",IF(M7>=90,"Excellent",IF(M7>=75,"Very Good",IF(M7>=60,"Good","Average")))) -> Good
A8: STU2025007 | B8: Isha Gupta | C8: 10 | D8: B | E8: Male | F8: Science Stream | G8: 69 | H8: 95 | I8: 43 | J8: 42 | K8: 74 | L8: =SUM(G8:K8) -> 323 | M8: =L8/500*100 -> 64.6 | N8: =VLOOKUP(M8,Grade_Scale!$A$3:$C$8,3,TRUE()) -> B | O8: =IF(AND(G8>=40,H8>=40,I8>=40,J8>=40,K8>=40),"Pass","Fail") -> Pass | P8: 96 | Q8: Pending | R8: =IF(O8="Fail","Needs Improvement",IF(M8>=90,"Excellent",IF(M8>=75,"Very Good",IF(M8>=60,"Good","Average")))) -> Good
A9: STU2025008 | B9: Rohan Singh | C9: 8 | D9: A | E9: Female | F9: Commerce Stream | G9: 56 | H9: 49 | I9: 98 | J9: 42 | K9: 62 | L9: =SUM(G9:K9) -> 307 | M9: =L9/500*100 -> 61.4 | N9: =VLOOKUP(M9,Grade_Scale!$A$3:$C$8,3,TRUE()) -> B | O9: =IF(AND(G9>=40,H9>=40,I9>=40,J9>=40,K9>=40),"Pass","Fail") -> Pass | P9: 78 | Q9: Paid | R9: =IF(O9="Fail","Needs Improvement",IF(M9>=90,"Excellent",IF(M9>=75,"Very Good",IF(M9>=60,"Good","Average")))) -> Good
A10: STU2025009 | B10: Yash Reddy | C10: 9 | D10: B | E10: Female | F10: Science Stream | G10: 56 | H10: 92 | I10: 86 | J10: 70 | K10: 52 | L10: =SUM(G10:K10) -> 356 | M10: =L10/500*100 -> 71.2 | N10: =VLOOKUP(M10,Grade_Scale!$A$3:$C$8,3,TRUE()) -> B | O10: =IF(AND(G10>=40,H10>=40,I10>=40,J10>=40,K10>=40),"Pass","Fail") -> Pass | P10: 87 | Q10: Pending | R10: =IF(O10="Fail","Needs Improvement",IF(M10>=90,"Excellent",IF(M10>=75,"Very Good",IF(M10>=60,"Good","Average")))) -> Good
A11: STU2025010 | B11: Dev Singh | C11: 8 | D11: C | E11: Female | F11: Science Stream | G11: 54 | H11: 45 | I11: 57 | J11: 54 | K11: 64 | L11: =SUM(G11:K11) -> 274 | M11: =L11/500*100 -> 54.8 | N11: =VLOOKUP(M11,Grade_Scale!$A$3:$C$8,3,TRUE()) -> C | O11: =IF(AND(G11>=40,H11>=40,I11>=40,J11>=40,K11>=40),"Pass","Fail") -> Pass | P11: 74 | Q11: Paid | R11: =IF(O11="Fail","Needs Improvement",IF(M11>=90,"Excellent",IF(M11>=75,"Very Good",IF(M11>=60,"Good","Average")))) -> Average
A12: STU2025011 | B12: Riya Rao | C12: 7 | D12: B | E12: Female | F12: Science Stream | G12: 53 | H12: 88 | I12: 82 | J12: 75 | K12: 51 | L12: =SUM(G12:K12) -> 349 | M12: =L12/500*100 -> 69.8 | N12: =VLOOKUP(M12,Grade_Scale!$A$3:$C$8,3,TRUE()) -> B | O12: =IF(AND(G12>=40,H12>=40,I12>=40,J12>=40,K12>=40),"Pass","Fail") -> Pass | P12: 92 | Q12: Paid | R12: =IF(O12="Fail","Needs Improvement",IF(M12>=90,"Excellent",IF(M12>=75,"Very Good",IF(M12>=60,"Good","Average")))) -> Good
A13: STU2025012 | B13: Kavya Nair | C13: 9 | D13: B | E13: Female | F13: Commerce Stream | G13: 48 | H13: 96 | I13: 86 | J13: 42 | K13: 59 | L13: =SUM(G13:K13) -> 331 | M13: =L13/500*100 -> 66.2 | N13: =VLOOKUP(M13,Grade_Scale!$A$3:$C$8,3,TRUE()) -> B | O13: =IF(AND(G13>=40,H13>=40,I13>=40,J13>=40,K13>=40),"Pass","Fail") -> Pass | P13: 64 | Q13: Paid | R13: =IF(O13="Fail","Needs Improvement",IF(M13>=90,"Excellent",IF(M13>=75,"Very Good",IF(M13>=60,"Good","Average")))) -> Good
... A61: STU2025060 | B61: Aditya Iyer | C61: 7 | D61: B | E61: Female | F61: Arts Stream | G61: 92 | H61: 90 | I61: 74 | J61: 37 | K61: 51 | L61: =SUM(G61:K61) -> 344 | M61: =L61/500*100 -> 68.8 | N61: =VLOOKUP(M61,Grade_Scale!$A$3:$C$8,3,TRUE()) -> B | O61: =IF(AND(G61>=40,H61>=40,I61>=40,J61>=40,K61>=40),"Pass","Fail") -> Fail | P61: 62 | Q61: Pending | R61: =IF(O61="Fail","Needs Improvement",IF(M61>=90,"Excellent",IF(M61>=75,"Very Good",IF(M61>=60,"Good","Average")))) -> Needs Improvement

Sheet Summary
A1: STUDENT MANAGEMENT SYSTEM - SUMMARY & KPIs
A3: KPI METRICS
A4: Total Students | B4: =COUNTA(Students_Data!A2:A61) -> 60
A5: Total Pass | B5: =COUNTIF(Students_Data!O2:O61,"Pass") -> 47
A6: Total Fail | B6: =COUNTIF(Students_Data!O2:O61,"Fail") -> 13
A7: Class Average (%) | B7: =AVERAGE(Students_Data!M2:M61) -> 67.166667
A8: Pending Fees Count | B8: =COUNTIF(Students_Data!Q2:Q61,"Pending") -> 33
A9: Top Scorer (Highest %) | B9: =MAX(Students_Data!M2:M61) -> 91.4
A11: Top Scorer (Name) | B11: =INDEX(Students_Data!B2:B61,MATCH(MAX(Students_Data!M2:M61),Students_Data!M2:M61,0)) -> Tanvi Verma
A14: GRADE DISTRIBUTION
A15: Grade | B15: Number of Students
A16: A+ | B16: =COUNTIF(Students_Data!$N$2:$N$61,A16) -> 1
A17: A | B17: =COUNTIF(Students_Data!$N$2:$N$61,A17) -> 11
A18: B | B18: =COUNTIF(Students_Data!$N$2:$N$61,A18) -> 37
A19: C | B19: =COUNTIF(Students_Data!$N$2:$N$61,A19) -> 10
A20: D | B20: =COUNTIF(Students_Data!$N$2:$N$61,A20) -> 1
A21: F | B21: =COUNTIF(Students_Data!$N$2:$N$61,A21) -> 0
A24: CLASS-WISE PERFORMANCE
A25: Class | B25: Total Students | C25: Average % | D25: Pass Count | E25: Total Marks (Sum)
A26: 6 | B26: =COUNTIF(Students_Data!$C$2:$C$61,A26) -> 13 | C26: =AVERAGEIF(Students_Data!$C$2:$C$61,A26,Students_Data!$M$2:$M$61) -> 64.538462 | D26: =COUNTIFS(Students_Data!$C$2:$C$61,A26,Students_Data!$O$2:$O$61,"Pass") -> 10 | E26: =SUMIF(Students_Data!$C$2:$C$61,A26,Students_Data!$L$2:$L$61) -> 4195
A27: 7 | B27: =COUNTIF(Students_Data!$C$2:$C$61,A27) -> 13 | C27: =AVERAGEIF(Students_Data!$C$2:$C$61,A27,Students_Data!$M$2:$M$61) -> 68.076923 | D27: =COUNTIFS(Students_Data!$C$2:$C$61,A27,Students_Data!$O$2:$O$61,"Pass") -> 10 | E27: =SUMIF(Students_Data!$C$2:$C$61,A27,Students_Data!$L$2:$L$61) -> 4425
A28: 8 | B28: =COUNTIF(Students_Data!$C$2:$C$61,A28) -> 10 | C28: =AVERAGEIF(Students_Data!$C$2:$C$61,A28,Students_Data!$M$2:$M$61) -> 66.32 | D28: =COUNTIFS(Students_Data!$C$2:$C$61,A28,Students_Data!$O$2:$O$61,"Pass") -> 7 | E28: =SUMIF(Students_Data!$C$2:$C$61,A28,Students_Data!$L$2:$L$61) -> 3316
A29: 9 | B29: =COUNTIF(Students_Data!$C$2:$C$61,A29) -> 12 | C29: =AVERAGEIF(Students_Data!$C$2:$C$61,A29,Students_Data!$M$2:$M$61) -> 68.716667 | D29: =COUNTIFS(Students_Data!$C$2:$C$61,A29,Students_Data!$O$2:$O$61,"Pass") -> 10 | E29: =SUMIF(Students_Data!$C$2:$C$61,A29,Students_Data!$L$2:$L$61) -> 4123
A30: 10 | B30: =COUNTIF(Students_Data!$C$2:$C$61,A30) -> 12 | C30: =AVERAGEIF(Students_Data!$C$2:$C$61,A30,Students_Data!$M$2:$M$61) -> 68.183333 | D30: =COUNTIFS(Students_Data!$C$2:$C$61,A30,Students_Data!$O$2:$O$61,"Pass") -> 10 | E30: =SUMIF(Students_Data!$C$2:$C$61,A30,Students_Data!$L$2:$L$61) -> 4091

Sheet Instructions
A1: HOW TO COMPLETE THE PIVOT TABLE, PIVOT CHART & SLICERS
A3: 1. Click any cell inside the 'Students_Data' table.
A4: 2. Go to Insert > PivotTable > New Worksheet. Name the sheet 'PivotTable'.
A5: 3. In the PivotTable Fields pane, drag 'Class' and 'Section' to ROWS.
A6: 4. Drag 'Percentage (%)' to VALUES and set it to Average; drag 'Result' to VALUES and set it to Count to get Pass/Fail counts.
A7: 5. Drag 'Gender' to COLUMNS to compare performance by gender.
A8: 6. Select the PivotTable, go to Insert > PivotChart, choose Clustered Column chart.
A9: 7. Select the PivotTable, go to Insert > Slicer.
A10: 8. Tick 'Class', 'Section', 'Gender', and 'Fee Status' to add four slicers.
A11: 9. Resize and arrange the slicers, pivot table, and pivot chart neatly on the sheet.
A12: 10. Click each slicer button to test interactive filtering of the chart and table.
A13: 11. (Optional) Copy/link the PivotChart onto the 'Dashboard' sheet for a single-view report.

Sheet README
A1: STUDENT MANAGEMENT SYSTEM - PROJECT README
A4: PROJECT OVERVIEW
A5: This workbook simulates a school's student management system. It tracks student records, subject-wise marks, attendance, fee status, and academic performance, presenting key insights through an interactive dashboard.
A7: SHEETS IN THIS WORKBOOK
A8: 1. Dashboard - KPI cards, charts, and overview visuals.
A9: 2. Students_Data - 60 student records with formulas (SUM, IF, nested IF, VLOOKUP), data validation dropdowns, and conditional formatting.
A10: 3. Grade_Scale - Lookup table used by VLOOKUP (approximate match) to assign grades.
A11: 4. Summary - KPI calculations and COUNTIF/AVERAGEIF/COUNTIFS aggregation tables feeding the Dashboard.
A12: 5. Instructions - Step-by-step guide to build the Pivot Table, Pivot Chart, and Slicers (must be added manually in Excel as openpyxl-generated files do not embed live pivot caches).
A14: HOW TO USE
A15: - Open the file in Microsoft Excel (desktop) for full functionality (data validation, conditional formatting, and charts are pre-built).
A16: - Follow the 'Instructions' sheet to add a Pivot Table, Pivot Chart, and Slicers for full interactivity - this is a quick 5-minute step in Excel's Insert menu.
... A18: - Edit marks/attendance in 'Students_Data' and all formulas, KPIs, and charts will recalculate automatically.
